Workbook
Name SegmentaciónDeDatos_CANT_UND2: #REF!
Name SegmentaciónDeDatos_Categoría: #REF!
Name SegmentaciónDeDatos_COMPRA: #REF!
Name SegmentaciónDeDatos_NEGOCIO: #REF!
Name SlicerCache_Table_1_Col_1: #N/A
Name SlicerCache_Table_1_Col_16: #N/A
Name SlicerCache_Table_1_Col_2: #N/A
Name SlicerCache_Table_1_Col_7: #N/A

Sheet CAT FOCO SEM1 SEP
C1: CERVEZA
C2: PCV
D5: =12+17+3+17 -> 49
F7: %Cer | G7: %Mal | H7: %Sang | I7: %Vinos | J7: % Cola Negra | K7: % Cola Blanca | L7: %Sab | M7: %Agua | N7: %Jug | O7: %Té | P7: %Beb.Depor. | Q7: %Mezcladores | R7: %Harina de Maíz | S7: %Margarinas | T7: %Mayonesas | U7: %Quesos | V7: %Achocolatados | W7: %Pepitonas | X7: %Atunes | Y7: %Cereales Infantiles | Z7: %Manteca | AA7: %Oleinas | AB7: %Ket | AC7: %Aceites | AD7: %Vin | AE7: %Arroz | AF7: %Past | AG7: %Avena | AH7: %Cafe | AI7: %Yogurt | AJ7: %Perros | AK7: %Gatos | AL7: %Sar | AM7: %Deter | AN7: %Multiuso | AO7: %Suavizantes de Ropa | AP7: %Limpiadores | AQ7: %Lavaplatos | AR7: %Jab | AS7: %Cuidado del Cabello | AT7: %Cuidado Femenino | AU7: %Cuidado Personal | AV7: %Cuidado del Bebé | AW7: %Cuidado Bucal | AX7: %Afeitado | AY7: ROCKSTAR | AZ7: MIN SPRK TOR P500 12U | BA7: MALTIN COCO
A8: CODIGO SISTEMA | B8: CEP | C8: DIA | D8: CLIENTE | E8: CLIENTES DE ADC
A9: 0190330032 | B9: 939228 | C9: LUNES | D9: DIAZ INVERSIONES LA ANDINA
A10: 0084357812 | B10: 84695 | C10: LUNES | D10: INVERSIONES ECONOMICASA
A11: 412818023 | B11: 945177 | C11: LUNES | D11: FARMACIA DEL AHORRO PEDRAZA, C.A | E11: 1 PUERTA
A12: 0084412364 | B12: 278935 | C12: LUNES | D12: YONGCUN WU / WU COMERCIAL LUNA 2014, F.P
A13: 175493685 | B13: 961367 | C13: LUNES | D13: BODEGON EL CALDEREÑO
A14: 128256373 | B14: 874150 | C14: LUNES | D14: CLUB DEPORTIVO EL JARDIN FP | E14: 1 PUERTA
A15: 0080090184 | B15: 632997 | C15: LUNES | D15: TORRES POSADA TURISTICA SANTOCRISTO A-Z
A16: V196206953 | B16: 936151 | C16: LUNES | D16: BELANDRIA PANADERIA CENTRAL ELIPAN F,P
A17: V099858687 | B17: 8408792 | C17: LUNES | D17: OMAIRA DEL CARMEN OCANTO
A18: 230228139 | B18: 8408877 | C18: MARTES | D18: JOSE ADRIAN VIRIGAY
A19: V169783388 | B19: 623584 | C19: MARTES | D19: MORENO INVERSIONES DON PALILLO F.P | E19: 1 PUERTA
A20: 0413051907 | B20: 959624 | C20: MARTES | D20: INVERSIONES ALJARAMANI | E20: 1 PUERTA
A21: 0153309953 | B21: 945055 | C21: MARTES | D21: PIDIACHI INVERSIONES MI TESORO, F.P
A22: 050326175 | B22: 549351 | C22: MARTES | D22: LICORES YENDER | E22: 1 PUERTA
A23: 103997077 | B23: 145691 | C23: MARTES | D23: REST. CERV. EL GRAN MESON | E23: 1 PUERTA
A24: 004881148 | B24: 78643 | C24: MARTES | D24: BAR REST PARIAGUAN | E24: 1 PUERTA
A25: 0009363745 | B25: 549506 | C25: MARTES | D25: LICORERIA LOS LAURELES | E25: 1 PUERTA
A26: 165750817 | B26: 960511 | C26: MARTES | D26: KARELIS YARUBI VILLARREAL CASTILLO
A27: 091811606 | B27: 623587 | C27: MARTES | D27: BODEGON EL AMANECER
A28: 0017550000 | B28: 701396 | C28: MARTES | D28: YASMIN DEL CARMEN PERNIA PEREZ | E28: 1 PUERTA
A29: 148679971 | B29: 943440 | C29: MARTES | D29: MORALES INV. EL LLANO, F.P | E29: 1 PUERTA
A30: 0230220332 | B30: 566611 | C30: MARTES | D30: SUAREZ RESTOBAR Y BODEGON DESTAPALA, F.P | E30: 1 PUERTA
A31: 093655857 | B31: 569007 | C31: MARTES | D31: CASTILLO BODEGON DON JOSE, F.P
A32: 0502689125 | B32: 949130 | C32: MARTES | D32: MULTI-INVERSIONES EL TAMARINDO, C.A | E32: 1 PUERTA
A33: 0065937405 | B33: 145712 | C33: MARTES | D33: VIVERES Y FRUTERIA EL CHAPARRAL
A34: 0408654261 | B34: 420131 | C34: MARTES | D34: ABASTO Y LICORERIA LA CHINA, C.A
A35: 192441214 | B35: 623573 | C35: MARTES | D35: BODEGON INVERSIONES VAMOS PA´ YI | E35: 1 PUERTA
A36: 0410773120 | B36: 936187 | C36: MARTES | D36: AVENDAÑO BODEGON EUKARY-G.E FP | E36: 1 PUERTA
A37: 036177027 | B37: 145626 | C37: MARTES | D37: CERVECERIA LA COPA DE ORO | E37: 1 PUERTA
A38: J411565342 | B38: 566628 | C38: MARTES | D38: LICORERIA EL MARACUCHO
A39: 0283771810 | B39: 8408938 | C39: MARTES | D39: GREGORIO ISAA MILLAN AGUIRRE
A40: 0081364881 | B40: 333777 | C40: MARTES | D40: LICORES EL VIÑEDO, F.P.
A41: CLTAINA-000050 | B41: 961522 | C41: MIERCOLES | D41: BELANDRIA SERVICARNES LOS COMPADRES, F.P.
B42: 145689 | C42: MIERCOLES | D42: VIVERES DONEY
A43: 0406629260 | B43: 893765 | C43: MIERCOLES | D43: CD MASTER, C.A
...

Sheet INVENTARIO
A10: NEGOCIO | B10: Categoría | C10: Marca | D10: COD | E10: DESC | F10: UND | G10: COMPRA | H10: UND2 | I10: SEM1 | J10: SEM2 | K10: VENTA | L10: SEM3 | M10: VENTA2 | N10: SEM4 | O10: SEM5 | P10: CANT UND2 | Q10: COMP | R10: VENTA | S10: VENTA2,1 | T10: VENTAS 3
A11: =VLOOKUP(INVENTARIO!$D11,LISTA!$A:$E,3,0) -> APC-FQ | B11: =VLOOKUP(INVENTARIO!$D11,LISTA!$A:$E,4,0) -> Yogurt | C11: =VLOOKUP(INVENTARIO!$D11,LISTA!$A:$E,5,0) -> MIGURT | D11: Y070 | E11: YOGURT SABOR NARANJA V-MIGURT 125GX24UND | F11: 24 | G11: =Q11 -> 0 | H11: =G11*F11 -> 0 | K11: =R11 -> 0 | M11: =S11 -> 0 | P11: =H11-J11-I11-K11-L11-M11-INVENTARIO!$N11-O11 -> 0 | Q11: =IFERROR(VLOOKUP(D11,'TABL COMPR'!$A:$D,4,0),0) -> 0 | R11: =IFERROR(VLOOKUP(D11,#REF!,4,0),0) -> 0 | S11: =IFERROR(VLOOKUP(D11,#REF!,4,0),0) -> 0 | T11: =IFERROR(VLOOKUP(D11,#REF!,4,0),0) -> 0
A12: =VLOOKUP(INVENTARIO!$D12,LISTA!$A:$E,3,0) -> APC-FQ | B12: =VLOOKUP(INVENTARIO!$D12,LISTA!$A:$E,4,0) -> Yogurt | C12: =VLOOKUP(INVENTARIO!$D12,LISTA!$A:$E,5,0) -> MIGURT | D12: Y069 | E12: YOGURT SABOR CAMBUR MIGURT 125GX24UND | F12: 24 | G12: =Q12 -> 0 | H12: =G12*F12 -> 0 | K12: =R12 -> 0 | M12: =S12 -> 0 | P12: =H12-J12-I12-K12-L12-M12-INVENTARIO!$N12-O12 -> 0 | Q12: =IFERROR(VLOOKUP(D12,'TABL COMPR'!$A:$D,4,0),0) -> 0 | R12: =IFERROR(VLOOKUP(D12,#REF!,4,0),0) -> 0 | S12: =IFERROR(VLOOKUP(D12,#REF!,4,0),0) -> 0 | T12: =IFERROR(VLOOKUP(D12,#REF!,4,0),0) -> 0
A13: =VLOOKUP(INVENTARIO!$D13,LISTA!$A:$E,3,0) -> APC-FQ | B13: =VLOOKUP(INVENTARIO!$D13,LISTA!$A:$E,4,0) -> Yogurt | C13: =VLOOKUP(INVENTARIO!$D13,LISTA!$A:$E,5,0) -> MIGURT | D13: Y036 | E13: YOGURT SABOR FRESA MIGURT 125GX24UND | F13: 24 | G13: =Q13 -> 0 | H13: =G13*F13 -> 0 | K13: =R13 -> 0 | M13: =S13 -> 0 | P13: =H13-J13-I13-K13-L13-M13-INVENTARIO!$N13-O13 -> 0 | Q13: =IFERROR(VLOOKUP(D13,'TABL COMPR'!$A:$D,4,0),0) -> 0 | R13: =IFERROR(VLOOKUP(D13,#REF!,4,0),0) -> 0 | S13: =IFERROR(VLOOKUP(D13,#REF!,4,0),0) -> 0 | T13: =IFERROR(VLOOKUP(D13,#REF!,4,0),0) -> 0
A14: =VLOOKUP(INVENTARIO!$D14,LISTA!$A:$E,3,0) -> APC-FQ | B14: =VLOOKUP(INVENTARIO!$D14,LISTA!$A:$E,4,0) -> Yogurt | C14: =VLOOKUP(INVENTARIO!$D14,LISTA!$A:$E,5,0) -> MIGURT | D14: Y007 | E14: YOGURT FRUTA FRESA MIGURT 750GX12UND BOT | F14: 12 | G14: =Q14 -> 0 | H14: =G14*F14 -> 0 | K14: =R14 -> 0 | M14: =S14 -> 0 | P14: =H14-J14-I14-K14-L14-M14-INVENTARIO!$N14-O14 -> 0 | Q14: =IFERROR(VLOOKUP(D14,'TABL COMPR'!$A:$D,4,0),0) -> 0 | R14: =IFERROR(VLOOKUP(D14,#REF!,4,0),0) -> 0 | S14: =IFERROR(VLOOKUP(D14,#REF!,4,0),0) -> 0 | T14: =IFERROR(VLOOKUP(D14,#REF!,4,0),0) -> 0
A15: =VLOOKUP(INVENTARIO!$D15,LISTA!$A:$E,3,0) -> APC-FQ | B15: =VLOOKUP(INVENTARIO!$D15,LISTA!$A:$E,4,0) -> Yogurt | C15: =VLOOKUP(INVENTARIO!$D15,LISTA!$A:$E,5,0) -> MIGURT | D15: Y005 | E15: YOGURT FRUTA DURAZNO MIGURT 250GX24UND | F15: 24 | G15: =Q15 -> 0 | H15: =G15*F15 -> 0 | K15: =R15 -> 0 | M15: =S15 -> 0 | P15: =H15-J15-I15-K15-L15-M15-INVENTARIO!$N15-O15 -> 0 | Q15: =IFERROR(VLOOKUP(D15,'TABL COMPR'!$A:$D,4,0),0) -> 0 | R15: =IFERROR(VLOOKUP(D15,#REF!,4,0),0) -> 0 | S15: =IFERROR(VLOOKUP(D15,#REF!,4,0),0) -> 0 | T15: =IFERROR(VLOOKUP(D15,#REF!,4,0),0) -> 0
A16: =VLOOKUP(INVENTARIO!$D16,LISTA!$A:$E,3,0) -> APC-FQ | B16: =VLOOKUP(INVENTARIO!$D16,LISTA!$A:$E,4,0) -> Yogurt | C16: =VLOOKUP(INVENTARIO!$D16,LISTA!$A:$E,5,0) -> MIGURT | D16: Y004 | E16: YOGURT FRUTA FRESA MIGURT 250GX24UND | F16: 24 | G16: =Q16 -> 0 | H16: =G16*F16 -> 0 | K16: =R16 -> 0 | M16: =S16 -> 0 | P16: =H16-J16-I16-K16-L16-M16-INVENTARIO!$N16-O16 -> 0 | Q16: =IFERROR(VLOOKUP(D16,'TABL COMPR'!$A:$D,4,0),0) -> 0 | R16: =IFERROR(VLOOKUP(D16,#REF!,4,0),0) -> 0 | S16: =IFERROR(VLOOKUP(D16,#REF!,4,0),0) -> 0 | T16: =IFERROR(VLOOKUP(D16,#REF!,4,0),0) -> 0
A17: =VLOOKUP(INVENTARIO!$D17,LISTA!$A:$E,3,0) -> APC-FQ | B17: =VLOOKUP(INVENTARIO!$D17,LISTA!$A:$E,4,0) -> Yogurt | C17: =VLOOKUP(INVENTARIO!$D17,LISTA!$A:$E,5,0) -> MIGURT | D17: Y002 | E17: YOGURT FRUTA DURAZNO MIGURT 125GX24UND | F17: 24 | G17: =Q17 -> 0 | H17: =G17*F17 -> 0 | K17: =R17 -> 0 | M17: =S17 -> 0 | P17: =H17-J17-I17-K17-L17-M17-INVENTARIO!$N17-O17 -> 0 | Q17: =IFERROR(VLOOKUP(D17,'TABL COMPR'!$A:$D,4,0),0) -> 0 | R17: =IFERROR(VLOOKUP(D17,#REF!,4,0),0) -> 0 | S17: =IFERROR(VLOOKUP(D17,#REF!,4,0),0) -> 0 | T17: =IFERROR(VLOOKUP(D17,#REF!,4,0),0) -> 0
A18: =VLOOKUP(INVENTARIO!$D18,LISTA!$A:$E,3,0) -> APC-FQ | B18: =VLOOKUP(INVENTARIO!$D18,LISTA!$A:$E,4,0) -> Yogurt | C18: =VLOOKUP(INVENTARIO!$D18,LISTA!$A:$E,5,0) -> MIGURT | D18: Y001 | E18: YOGURT FRUTA FRESA MIGURT 125GX24UND | F18: 24 | G18: =Q18 -> 0 | H18: =G18*F18 -> 0 | K18: =R18 -> 0 | M18: =S18 -> 0 | P18: =H18-J18-I18-K18-L18-M18-INVENTARIO!$N18-O18 -> 0 | Q18: =IFERROR(VLOOKUP(D18,'TABL COMPR'!$A:$D,4,0),0) -> 0 | R18: =IFERROR(VLOOKUP(D18,#REF!,4,0),0) -> 0 | S18: =IFERROR(VLOOKUP(D18,#REF!,4,0),0) -> 0 | T18: =IFERROR(VLOOKUP(D18,#REF!,4,0),0) -> 0
A19: =VLOOKUP(INVENTARIO!$D19,LISTA!$A:$E,3,0) -> APC-FQ | B19: =VLOOKUP(INVENTARIO!$D19,LISTA!$A:$E,4,0) -> HARINA DE MAIZ | C19: =VLOOKUP(INVENTARIO!$D19,LISTA!$A:$E,5,0) -> PAN | D19: H187 | E19: PAN HPM BLANCO GLUTEN FREE 1KGX20UN VE | F19: 20 | G19: =Q19 -> 0 | H19: =G19*F19 -> 0 | K19: =R19 -> 0 | M19: =S19 -> 0 | P19: =H19-J19-I19-K19-L19-M19-INVENTARIO!$N19-O19 -> 0 | Q19: =IFERROR(VLOOKUP(D19,'TABL COMPR'!$A:$D,4,0),0) -> 0 | R19: =IFERROR(VLOOKUP(D19,#REF!,4,0),0) -> 0 | S19: =IFERROR(VLOOKUP(D19,#REF!,4,0),0) -> 0 | T19: =IFERROR(VLOOKUP(D19,#REF!,4,0),0) -> 0
A20: =VLOOKUP(INVENTARIO!$D20,LISTA!$A:$E,3,0) -> APC-FQ | B20: =VLOOKUP(INVENTARIO!$D20,LISTA!$A:$E,4,0) -> MAYONESAS | C20: =VLOOKUP(INVENTARIO!$D20,LISTA!$A:$E,5,0) -> MAVESA | D20: T020 | E20: MAVESA MAYONESA 445Gx12UN | F20: 12 | G20: =Q20 -> 0 | H20: =G20*F20 -> 0 | K20: =R20 -> 0 | M20: =S20 -> 0 | P20: =H20-J20-I20-K20-L20-M20-INVENTARIO!$N20-O20 -> 0 | Q20: =IFERROR(VLOOKUP(D20,'TABL COMPR'!$A:$D,4,0),0) -> 0 | R20: =IFERROR(VLOOKUP(D20,#REF!,4,0),0) -> 0 | S20: =IFERROR(VLOOKUP(D20,#REF!,4,0),0) -> 0 | T20: =IFERROR(VLOOKUP(D20,#REF!,4,0),0) -> 0
A21: =VLOOKUP(INVENTARIO!$D21,LISTA!$A:$E,3,0) -> APC-FQ | B21: =VLOOKUP(INVENTARIO!$D21,LISTA!$A:$E,4,0) -> KETCHUP | C21: =VLOOKUP(INVENTARIO!$D21,LISTA!$A:$E,5,0) -> PAMPERO | D21: T061 | E21: PAMPERO KETCHUP 397Gx24UN | F21: 24 | G21: =Q21 -> 0 | H21: =G21*F21 -> 0 | K21: =R21 -> 0 | M21: =S21 -> 0 | P21: =H21-J21-I21-K21-L21-M21-INVENTARIO!$N21-O21 -> 0 | Q21: =IFERROR(VLOOKUP(D21,'TABL COMPR'!$A:$D,4,0),0) -> 0 | R21: =IFERROR(VLOOKUP(D21,#REF!,4,0),0) -> 0 | S21: =IFERROR(VLOOKUP(D21,#REF!,4,0),0) -> 0 | T21: =IFERROR(VLOOKUP(D21,#REF!,4,0),0) -> 0
A22: =VLOOKUP(INVENTARIO!$D22,LISTA!$A:$E,3,0) -> APC-FQ | B22: =VLOOKUP(INVENTARIO!$D22,LISTA!$A:$E,4,0) -> MARGARINA | C22: =VLOOKUP(INVENTARIO!$D22,LISTA!$A:$E,5,0) -> MAVESA | D22: T595 | E22: MAVESA MARGARINA 250Gx24UN | F22: 24 | G22: =Q22 -> 0 | H22: =G22*F22 -> 0 | K22: =R22 -> 0 | M22: =S22 -> 0 | P22: =H22-J22-I22-K22-L22-M22-INVENTARIO!$N22-O22 -> 0 | Q22: =IFERROR(VLOOKUP(D22,'TABL COMPR'!$A:$D,4,0),0) -> 0 | R22: =IFERROR(VLOOKUP(D22,#REF!,4,0),0) -> 0 | S22: =IFERROR(VLOOKUP(D22,#REF!,4,0),0) -> 0 | T22: =IFERROR(VLOOKUP(D22,#REF!,4,0),0) -> 0
... A36: =VLOOKUP(INVENTARIO!$D36,LISTA!$A:$E,3,0) -> APC-FQ | B36: =VLOOKUP(INVENTARIO!$D36,LISTA!$A:$E,4,0) -> MAYONESAS | C36: =VLOOKUP(INVENTARIO!$D36,LISTA!$A:$E,5,0) -> MAVESA | D36: T018 | E36: MAVESA MAYONESA 910Gx6UN | F36: 6 | G36: =Q36 -> 0 | H36: =G36*F36 -> 0 | K36: =R36 -> 0 | M36: =S36 -> 0 | P36: =H36-J36-I36-K36-L36-M36-INVENTARIO!$N36-O36 -> 0 | Q36: =IFERROR(VLOOKUP(D36,'TABL COMPR'!$A:$D,4,0),0) -> 0 | R36: =IFERROR(VLOOKUP(D36,#REF!,4,0),0) -> 0 | S36: =IFERROR(VLOOKUP(D36,#REF!,4,0),0) -> 0 | T36: =IFERROR(VLOOKUP(D36,#REF!,4,0),0) -> 0
A37: =VLOOKUP(INVENTARIO!$D37,LISTA!$A:$E,3,0) -> APC-FQ | B37: =VLOOKUP(INVENTARIO!$D37,LISTA!$A:$E,4,0) -> MODIFICADORES LACTEOS BEBIDAS | C37: =VLOOKUP(INVENTARIO!$D37,LISTA!$A:$E,5,0) -> TODDY | D37: T003 | E37: TODDY BOLSA 400GX24UN | F37: 24 | G37: 0 | H37: =G37*F37 -> 0 | K37: =R37 -> 0 | M37: =S37 -> 0 | P37: =H37-J37-I37-K37-L37-M37-INVENTARIO!$N37-O37 -> 0 | Q37: =IFERROR(VLOOKUP(D37,'TABL COMPR'!$A:$D,4,0),0) -> 0 | R37: =IFERROR(VLOOKUP(D37,#REF!,4,0),0) -> 0 | S37: =IFERROR(VLOOKUP(D37,#REF!,4,0),0) -> 0 | T37: =IFERROR(VLOOKUP(D37,#REF!,4,0),0) -> 0
A38: =VLOOKUP(INVENTARIO!$D38,LISTA!$A:$E,3,0) -> APC-FQ | B38: =VLOOKUP(INVENTARIO!$D38,LISTA!$A:$E,4,0) -> MODIFICADORES LACTEOS BEBIDAS | C38: =VLOOKUP(INVENTARIO!$D38,LISTA!$A:$E,5,0) -> TODDY | D38: T002 | E38: TODDY 2KGx8UN | F38: 8 | G38: =Q38 -> 0 | H38: =G38*F38 -> 0 | K38: =R38 -> 0 | M38: =S38 -> 0 | P38: =H38-J38-I38-K38-L38-M38-INVENTARIO!$N38-O38 -> 0 | Q38: =IFERROR(VLOOKUP(D38,'TABL COMPR'!$A:$D,4,0),0) -> 0 | R38: =IFERROR(VLOOKUP(D38,#REF!,4,0),0) -> 0 | S38: =IFERROR(VLOOKUP(D38,#REF!,4,0),0) -> 0 | T38: =IFERROR(VLOOKUP(D38,#REF!,4,0),0) -> 0
A39: =VLOOKUP(INVENTARIO!$D39,LISTA!$A:$E,3,0) -> APC-FQ | B39: =VLOOKUP(INVENTARIO!$D39,LISTA!$A:$E,4,0) -> VINAGRES | C39: =VLOOKUP(INVENTARIO!$D39,LISTA!$A:$E,5,0) -> MAVESA | D39: T049 | E39: MAVESA VINAGRE 500MLx24UN | F39: 24 | G39: =Q39 -> 0 | H39: =G39*F39 -> 0 | K39: =R39 -> 0 | M39: =S39 -> 0 | P39: =H39-J39-I39-K39-L39-M39-INVENTARIO!$N39-O39 -> 0 | Q39: =IFERROR(VLOOKUP(D39,'TABL COMPR'!$A:$D,4,0),0) -> 0 | R39: =IFERROR(VLOOKUP(D39,#REF!,4,0),0) -> 0 | S39: =IFERROR(VLOOKUP(D39,#REF!,4,0),0) -> 0 | T39: =IFERROR(VLOOKUP(D39,#REF!,4,0),0) -> 0
A40: =VLOOKUP(INVENTARIO!$D40,LISTA!$A:$E,3,0) -> APC-FQ | B40: =VLOOKUP(INVENTARIO!$D40,LISTA!$A:$E,4,0) -> KETCHUP | C40: =VLOOKUP(INVENTARIO!$D40,LISTA!$A:$E,5,0) -> PAMPERO | D40: T060 | E40: KETCHUP PAMPERO 198 G X 24 UND | F40: 24 | G40: =Q40 -> 0 | H40: =G40*F40 -> 0 | K40: =R40 -> 0 | M40: =S40 -> 0 | P40: =H40-J40-I40-K40-L40-M40-INVENTARIO!$N40-O40 -> 0 | Q40: =IFERROR(VLOOKUP(D40,'TABL COMPR'!$A:$D,4,0),0) -> 0 | R40: =IFERROR(VLOOKUP(D40,#REF!,4,0),0) -> 0 | S40: =IFERROR(VLOOKUP(D40,#REF!,4,0),0) -> 0 | T40: =IFERROR(VLOOKUP(D40,#REF!,4,0),0) -> 0
A41: =VLOOKUP(INVENTARIO!$D41,LISTA!$A:$E,3,0) -> APC-FQ | B41: =VLOOKUP(INVENTARIO!$D41,LISTA!$A:$E,4,0) -> BEBIDAS INSTANTANEAS | C41: =VLOOKUP(INVENTARIO!$D41,LISTA!$A:$E,5,0) -> KONGA | D41: Q142 | E41: KONGA PAPELON CON LIMON 30GX8X14UNI | F41: 14 | G41: =Q41 -> 0 | H41: =G41*F41 -> 0 | K41: =R41 -> 0 | M41: =S41 -> 0 | P41: =H41-J41-I41-K41-L41-M41-INVENTARIO!$N41-O41 -> 0 | Q41: =IFERROR(VLOOKUP(D41,'TABL COMPR'!$A:$D,4,0),0) -> 0 | R41: =IFERROR(VLOOKUP(D41,#REF!,4,0),0) -> 0 | S41: =IFERROR(VLOOKUP(D41,#REF!,4,0),0) -> 0 | T41: =IFERROR(VLOOKUP(D41,#REF!,4,0),0) -> 0
A42: =VLOOKUP(INVENTARIO!$D42,LISTA!$A:$E,3,0) -> APC-FQ | B42: =VLOOKUP(INVENTARIO!$D42,LISTA!$A:$E,4,0) -> BEBIDAS INSTANTANEAS | C42: =VLOOKUP(INVENTARIO!$D42,LISTA!$A:$E,5,0) -> KONGA | D42: Q141 | E42: KONGA SABOR DURAZNO 30GX8X14UN | F42: 14 | G42: =Q42 -> 0 | H42: =G42*F42 -> 0 | K42: =R42 -> 0 | M42: =S42 -> 0 | P42: =H42-J42-I42-K42-L42-M42-INVENTARIO!$N42-O42 -> 0 | Q42: =IFERROR(VLOOKUP(D42,'TABL COMPR'!$A:$D,4,0),0) -> 0 | R42: =IFERROR(VLOOKUP(D42,#REF!,4,0),0) -> 0 | S42: =IFERROR(VLOOKUP(D42,#REF!,4,0),0) -> 0 | T42: =IFERROR(VLOOKUP(D42,#REF!,4,0),0) -> 0
A43: =VLOOKUP(INVENTARIO!$D43,LISTA!$A:$E,3,0) -> APC-FQ | B43: =VLOOKUP(INVENTARIO!$D43,LISTA!$A:$E,4,0) -> BEBIDAS INSTANTANEAS | C43: =VLOOKUP(INVENTARIO!$D43,LISTA!$A:$E,5,0) -> KONGA | D43: Q140 | E43: KONGA SABOR TIZANA 30GX8X14UN | F43: 14 | G43: =Q43 -> 0 | H43: =G43*F43 -> 0 | K43: =R43 -> 0 | M43: =S43 -> 0 | P43: =H43-J43-I43-K43-L43-M43-INVENTARIO!$N43-O43 -> 0 | Q43: =IFERROR(VLOOKUP(D43,'TABL COMPR'!$A:$D,4,0),0) -> 0 | R43: =IFERROR(VLOOKUP(D43,#REF!,4,0),0) -> 0 | S43: =IFERROR(VLOOKUP(D43,#REF!,4,0),0) -> 0 | T43: =IFERROR(VLOOKUP(D43,#REF!,4,0),0) -> 0
A44: =VLOOKUP(INVENTARIO!$D44,LISTA!$A:$E,3,0) -> APC-FQ | B44: =VLOOKUP(INVENTARIO!$D44,LISTA!$A:$E,4,0) -> AVENAS | C44: =VLOOKUP(INVENTARIO!$D44,LISTA!$A:$E,5,0) -> QUAKER | D44: Q137 | E44: QUAKER AVENA ORIGINAL BOLSA 200Gx30UN | F44: 30 | G44: =Q44 -> 0 | H44: =G44*F44 -> 0 | K44: =R44 -> 0 | M44: =S44 -> 0 | P44: =H44-J44-I44-K44-L44-M44-INVENTARIO!$N44-O44 -> 0 | Q44: =IFERROR(VLOOKUP(D44,'TABL COMPR'!$A:$D,4,0),0) -> 0 | R44: =IFERROR(VLOOKUP(D44,#REF!,4,0),0) -> 0 | S44: =IFERROR(VLOOKUP(D44,#REF!,4,0),0) -> 0 | T44: =IFERROR(VLOOKUP(D44,#REF!,4,0),0) -> 0
A45: =VLOOKUP(INVENTARIO!$D45,LISTA!$A:$E,3,0) -> APC-FQ | B45: =VLOOKUP(INVENTARIO!$D45,LISTA!$A:$E,4,0) -> BEBIDAS INSTANTANEAS | C45: =VLOOKUP(INVENTARIO!$D45,LISTA!$A:$E,5,0) -> KONGA | D45: Q123 | E45: KONGA SABOR PARCHITA 30GX8X14UN | F45: 14 | G45: =Q45 -> 0 | H45: =G45*F45 -> 0 | K45: =R45 -> 0 | M45: =S45 -> 0 | P45: =H45-J45-I45-K45-L45-M45-INVENTARIO!$N45-O45 -> 0 | Q45: =IFERROR(VLOOKUP(D45,'TABL COMPR'!$A:$D,4,0),0) -> 0 | R45: =IFERROR(VLOOKUP(D45,#REF!,4,0),0) -> 0 | S45: =IFERROR(VLOOKUP(D45,#REF!,4,0),0) -> 0 | T45: =IFERROR(VLOOKUP(D45,#REF!,4,0),0) -> 0
A46: =VLOOKUP(INVENTARIO!$D46,LISTA!$A:$E,3,0) -> APC-FQ | B46: =VLOOKUP(INVENTARIO!$D46,LISTA!$A:$E,4,0) -> BEBIDAS INSTANTANEAS | C46: =VLOOKUP(INVENTARIO!$D46,LISTA!$A:$E,5,0) -> KONGA | D46: Q114 | E46: KONGA SABOR NARANJA 30GX8X14UN | F46: 14 | G46: =Q46 -> 0 | H46: =G46*F46 -> 0 | K46: =R46 -> 0 | M46: =S46 -> 0 | P46: =H46-J46-I46-K46-L46-M46-INVENTARIO!$N46-O46 -> 0 | Q46: =IFERROR(VLOOKUP(D46,'TABL COMPR'!$A:$D,4,0),0) -> 0 | R46: =IFERROR(VLOOKUP(D46,#REF!,4,0),0) -> 0 | S46: =IFERROR(VLOOKUP(D46,#REF!,4,0),0) -> 0 | T46: =IFERROR(VLOOKUP(D46,#REF!,4,0),0) -> 0
A47: =VLOOKUP(INVENTARIO!$D47,LISTA!$A:$E,3,0) -> APC-FQ | B47: =VLOOKUP(INVENTARIO!$D47,LISTA!$A:$E,4,0) -> BEBIDAS INSTANTANEAS | C47: =VLOOKUP(INVENTARIO!$D47,LISTA!$A:$E,5,0) -> KONGA | D47: Q113 | E47: KONGA SABOR LIMON 30GX8X14UN | F47: 14 | G47: =Q47 -> 0 | H47: =G47*F47 -> 0 | K47: =R47 -> 0 | M47: =S47 -> 0 | P47: =H47-J47-I47-K47-L47-M47-INVENTARIO!$N47-O47 -> 0 | Q47: =IFERROR(VLOOKUP(D47,'TABL COMPR'!$A:$D,4,0),0) -> 0 | R47: =IFERROR(VLOOKUP(D47,#REF!,4,0),0) -> 0 | S47: =IFERROR(VLOOKUP(D47,#REF!,4,0),0) -> 0 | T47: =IFERROR(VLOOKUP(D47,#REF!,4,0),0) -> 0
A48: =VLOOKUP(INVENTARIO!$D48,LISTA!$A:$E,3,0) -> APC-FQ | B48: =VLOOKUP(INVENTARIO!$D48,LISTA!$A:$E,4,0) -> AVENAS | C48: =VLOOKUP(INVENTARIO!$D48,LISTA!$A:$E,5,0) -> QUAKER | D48: Q023 | E48: QUAKER HARINA DE AVENA (BOLS) 400Gx24UN | F48: 24 | G48: =Q48 -> 0 | H48: =G48*F48 -> 0 | K48: =R48 -> 0 | M48: =S48 -> 0 | P48: =H48-J48-I48-K48-L48-M48-INVENTARIO!$N48-O48 -> 0 | Q48: =IFERROR(VLOOKUP(D48,'TABL COMPR'!$A:$D,4,0),0) -> 0 | R48: =IFERROR(VLOOKUP(D48,#REF!,4,0),0) -> 0 | S48: =IFERROR(VLOOKUP(D48,#REF!,4,0),0) -> 0 | T48: =IFERROR(VLOOKUP(D48,#REF!,4,0),0) -> 0
A49: =VLOOKUP(INVENTARIO!$D49,LISTA!$A:$E,3,0) -> APC-FQ | B49: =VLOOKUP(INVENTARIO!$D49,LISTA!$A:$E,4,0) -> AVENAS | C49: =VLOOKUP(INVENTARIO!$D49,LISTA!$A:$E,5,0) -> QUAKER | D49: Q001 | E49: QUAKER AVENA ORIGINAL BOLSA 400Gx24UN | F49: 24 | G49: =Q49 -> 0 | H49: =G49*F49 -> 0 | K49: =R49 -> 0 | M49: =S49 -> 0 | P49: =H49-J49-I49-K49-L49-M49-INVENTARIO!$N49-O49 -> 0 | Q49: =IFERROR(VLOOKUP(D49,'TABL COMPR'!$A:$D,4,0),0) -> 0 | R49: =IFERROR(VLOOKUP(D49,#REF!,4,0),0) -> 0 | S49: =IFERROR(VLOOKUP(D49,#REF!,4,0),0) -> 0 | T49: =IFERROR(VLOOKUP(D49,#REF!,4,0),0) -> 0
... A159: =VLOOKUP(INVENTARIO!$D159,LISTA!$A:$E,3,0) -> APC-FQ | B159: =VLOOKUP(INVENTARIO!$D159,LISTA!$A:$E,4,0) -> CAFE | C159: =VLOOKUP(INVENTARIO!$D159,LISTA!$A:$E,5,0) -> BUEN CAFE | D159: C213 | E159: BUEN CAFE PREMIUM 500Gx10UN | F159: 10 | G159: =Q159 -> 0 | H159: =G159*F159 -> 0 | K159: =R159 -> 0 | M159: =S159 -> 0 | P159: =H159-J159-I159-K159-L159-M159-INVENTARIO!$N159-O159 -> 0 | Q159: =IFERROR(VLOOKUP(D159,'TABL COMPR'!$A:$D,4,0),0) -> 0 | R159: =IFERROR(VLOOKUP(D159,#REF!,4,0),0) -> 0 | S159: =IFERROR(VLOOKUP(D159,#REF!,4,0),0) -> 0 | T159: =IFERROR(VLOOKUP(D159,#REF!,4,0),0) -> 0
A160: =VLOOKUP(INVENTARIO!$D160,LISTA!$A:$E,3,0) -> CYM-FQ | B160: =VLOOKUP(INVENTARIO!$D160,LISTA!$A:$E,4,0) -> Light | C160: =VLOOKUP(INVENTARIO!$D160,LISTA!$A:$E,5,0) -> Polar Light | D160: F04005 | E160: POLAR LIGHT RET 222MLx36UN | F160: 36 | G160: =Q160 -> 0 | H160: =G160 -> 0 | K160: =R160 -> 0 | M160: =S160 -> 0 | P160: =H160-J160-I160-K160-L160-M160-INVENTARIO!$N160-O160 -> 0 | Q160: =IFERROR(VLOOKUP(D160,'TABL COMPR'!$A:$D,4,0),0) -> 0 | R160: =IFERROR(VLOOKUP(D160,#REF!,4,0),0) -> 0 | S160: =IFERROR(VLOOKUP(D160,#REF!,4,0),0) -> 0 | T160: =IFERROR(VLOOKUP(D160,#REF!,4,0),0) -> 0
A161: =VLOOKUP(INVENTARIO!$D161,LISTA!$A:$E,3,0) -> CYM-FQ | B161: =VLOOKUP(INVENTARIO!$D161,LISTA!$A:$E,4,0) -> Light | C161: =VLOOKUP(INVENTARIO!$D161,LISTA!$A:$E,5,0) -> Solera Light | D161: F03016 | E161: SOLERA LIGHT LAT 250MLx24UN | F161: 24 | G161: =Q161 -> 0 | H161: =G161 -> 0 | K161: =R161 -> 0 | M161: =S161 -> 0 | P161: =H161-J161-I161-K161-L161-M161-INVENTARIO!$N161-O161 -> 0 | Q161: =IFERROR(VLOOKUP(D161,'TABL COMPR'!$A:$D,4,0),0) -> 0 | R161: =IFERROR(VLOOKUP(D161,#REF!,4,0),0) -> 0 | S161: =IFERROR(VLOOKUP(D161,#REF!,4,0),0) -> 0 | T161: =IFERROR(VLOOKUP(D161,#REF!,4,0),0) -> 0
A162: CYM-FQ | B162: Light | C162: Solera Light | D162: F03090 | E162: SOLERA LIGHT LAT SLEEK 355MLX24UN | F162: 24 | G162: =Q162 -> 0 | H162: =G162 -> 0 | K162: =R162 -> 0 | M162: =S162 -> 0 | P162: =H162-J162-I162-K162-L162-M162-INVENTARIO!$N162-O162 -> 0 | Q162: =IFERROR(VLOOKUP(D162,'TABL COMPR'!$A:$D,4,0),0) -> 0 | R162: =IFERROR(VLOOKUP(D162,#REF!,4,0),0) -> 0 | S162: =IFERROR(VLOOKUP(D162,#REF!,4,0),0) -> 0 | T162: =IFERROR(VLOOKUP(D162,#REF!,4,0),0) -> 0
A163: =VLOOKUP(INVENTARIO!$D163,LISTA!$A:$E,3,0) -> CYM-FQ | B163: =VLOOKUP(INVENTARIO!$D163,LISTA!$A:$E,4,0) -> Tradicional | C163: =VLOOKUP(INVENTARIO!$D163,LISTA!$A:$E,5,0) -> Polar Pilsen | D163: F01001 | E163: POLAR PILSEN RET 222MLx36UN | F163: 36 | G163: =Q163 -> 0 | H163: =G163 -> 0 | K163: =R163 -> 0 | M163: =S163 -> 0 | P163: =H163-J163-I163-K163-L163-M163-INVENTARIO!$N163-O163 -> 0 | Q163: =IFERROR(VLOOKUP(D163,'TABL COMPR'!$A:$D,4,0),0) -> 0 | R163: =IFERROR(VLOOKUP(D163,#REF!,4,0),0) -> 0 | S163: =IFERROR(VLOOKUP(D163,#REF!,4,0),0) -> 0 | T163: =IFERROR(VLOOKUP(D163,#REF!,4,0),0) -> 0
A164: =VLOOKUP(INVENTARIO!$D164,LISTA!$A:$E,3,0) -> CYM-FQ | B164: =VLOOKUP(INVENTARIO!$D164,LISTA!$A:$E,4,0) -> Premiun | C164: =VLOOKUP(INVENTARIO!$D164,LISTA!$A:$E,5,0) -> Solera | D164: F03030 | E164: SOLERA RET 222MLx36UN | F164: 36 | G164: =Q164 -> 0 | H164: =G164 -> 0 | K164: =R164 -> 0 | M164: =S164 -> 0 | P164: =H164-J164-I164-K164-L164-M164-INVENTARIO!$N164-O164 -> 0 | Q164: =IFERROR(VLOOKUP(D164,'TABL COMPR'!$A:$D,4,0),0) -> 0 | R164: =IFERROR(VLOOKUP(D164,#REF!,4,0),0) -> 0 | S164: =IFERROR(VLOOKUP(D164,#REF!,4,0),0) -> 0 | T164: =IFERROR(VLOOKUP(D164,#REF!,4,0),0) -> 0
A165: =VLOOKUP(INVENTARIO!$D165,LISTA!$A:$E,3,0) -> CYM-FQ | B165: =VLOOKUP(INVENTARIO!$D165,LISTA!$A:$E,4,0) -> Premiun | C165: =VLOOKUP(INVENTARIO!$D165,LISTA!$A:$E,5,0) -> Solera Alt | D165: F06068 | E165: SOLERA BOHEMIA LAT 250MLx24UN | F165: 24 | G165: =Q165 -> 0 | H165: =INVENTARIO!$G165 -> 0 | K165: =R165 -> 0 | M165: =S165 -> 0 | P165: =H165-J165-I165-K165-L165-M165-INVENTARIO!$N165-O165 -> 0 | Q165: =IFERROR(VLOOKUP(D165,'TABL COMPR'!$A:$D,4,0),0) -> 0 | R165: =IFERROR(VLOOKUP(D165,#REF!,4,0),0) -> 0 | S165: =IFERROR(VLOOKUP(D165,#REF!,4,0),0) -> 0 | T165: =IFERROR(VLOOKUP(D165,#REF!,4,0),0) -> 0
A166: =VLOOKUP(INVENTARIO!$D166,LISTA!$A:$E,3,0) -> CYM-FQ | B166: =VLOOKUP(INVENTARIO!$D166,LISTA!$A:$E,4,0) -> Premiun | C166: =VLOOKUP(INVENTARIO!$D166,LISTA!$A:$E,5,0) -> Solera | D166: F03001 | E166: SOLERA LAT 250MLx24UN | F166: 24 | G166: =Q166 -> 0 | H166: =G166 -> 0 | K166: =R166 -> 0 | M166: =S166 -> 0 | P166: =H166-J166-I166-K166-L166-M166-INVENTARIO!$N166-O166 -> 0 | Q166: =IFERROR(VLOOKUP(D166,'TABL COMPR'!$A:$D,4,0),0) -> 0 | R166: =IFERROR(VLOOKUP(D166,#REF!,4,0),0) -> 0 | S166: =IFERROR(VLOOKUP(D166,#REF!,4,0),0) -> 0 | T166: =IFERROR(VLOOKUP(D166,#REF!,4,0),0) -> 0
A167: =VLOOKUP(INVENTARIO!$D167,LISTA!$A:$E,3,0) -> CYM-FQ | B167: =VLOOKUP(INVENTARIO!$D167,LISTA!$A:$E,4,0) -> Light | C167: =VLOOKUP(INVENTARIO!$D167,LISTA!$A:$E,5,0) -> Polar Light | D167: F04014 | E167: POLAR LIGHT LAT 250MLx24UN | F167: 24 | G167: =Q167 -> 0 | H167: =G167 -> 0 | K167: =R167 -> 0 | M167: =S167 -> 0 | P167: =H167-J167-I167-K167-L167-M167-INVENTARIO!$N167-O167 -> 0 | Q167: =IFERROR(VLOOKUP(D167,'TABL COMPR'!$A:$D,4,0),0) -> 0 | R167: =IFERROR(VLOOKUP(D167,#REF!,4,0),0) -> 0 | S167: =IFERROR(VLOOKUP(D167,#REF!,4,0),0) -> 0 | T167: =IFERROR(VLOOKUP(D167,#REF!,4,0),0) -> 0
A168: =VLOOKUP(INVENTARIO!$D168,LISTA!$A:$E,3,0) -> CYM-FQ | B168: =VLOOKUP(INVENTARIO!$D168,LISTA!$A:$E,4,0) -> Sangría | C168: =VLOOKUP(INVENTARIO!$D168,LISTA!$A:$E,5,0) -> Caroreña | D168: FR0159 | E168: SANGRIA CAROREÑA VERANO MOJITO LAT355x24 | F168: 24 | G168: =Q168 -> 0 | H168: =G168*F168 -> 0 | K168: =R168 -> 0 | M168: =S168 -> 0 | P168: =H168-J168-I168-K168-L168-M168-INVENTARIO!$N168-O168 -> 0 | Q168: =IFERROR(VLOOKUP(D168,'TABL COMPR'!$A:$D,4,0),0) -> 0 | R168: =IFERROR(VLOOKUP(D168,#REF!,4,0),0) -> 0 | S168: =IFERROR(VLOOKUP(D168,#REF!,4,0),0) -> 0 | T168: =IFERROR(VLOOKUP(D168,#REF!,4,0),0) -> 0
A169: =VLOOKUP(INVENTARIO!$D169,LISTA!$A:$E,3,0) -> CYM-FQ | B169: =VLOOKUP(INVENTARIO!$D169,LISTA!$A:$E,4,0) -> Sangría | C169: =VLOOKUP(INVENTARIO!$D169,LISTA!$A:$E,5,0) -> Caroreña | D169: FR0154 | E169: SANGRIA CAROREÑA VERANO MOJITO LAT355x12 | F169: 12 | G169: =Q169 -> 0 | H169: =G169 -> 0 | K169: =R169 -> 0 | M169: =S169 -> 0 | P169: =H169-J169-I169-K169-L169-M169-INVENTARIO!$N169-O169 -> 0 | Q169: =IFERROR(VLOOKUP(D169,'TABL COMPR'!$A:$D,4,0),0) -> 0 | R169: =IFERROR(VLOOKUP(D169,#REF!,4,0),0) -> 0 | S169: =IFERROR(VLOOKUP(D169,#REF!,4,0),0) -> 0 | T169: =IFERROR(VLOOKUP(D169,#REF!,4,0),0) -> 0
A170: =VLOOKUP(INVENTARIO!$D170,LISTA!$A:$E,3,0) -> CYM-FQ | B170: =VLOOKUP(INVENTARIO!$D170,LISTA!$A:$E,4,0) -> Sangría | C170: =VLOOKUP(INVENTARIO!$D170,LISTA!$A:$E,5,0) -> Caroreña | D170: FR0153 | E170: SANGRIA CAROREÑA VERANO BLANCA LAT250X12 | F170: 12 | G170: =Q170 -> 0 | H170: =G170 -> 0 | K170: =R170 -> 0 | M170: =S170 -> 0 | P170: =H170-J170-I170-K170-L170-M170-INVENTARIO!$N170-O170 -> 0 | Q170: =IFERROR(VLOOKUP(D170,'TABL COMPR'!$A:$D,4,0),0) -> 0 | R170: =IFERROR(VLOOKUP(D170,#REF!,4,0),0) -> 0 | S170: =IFERROR(VLOOKUP(D170,#REF!,4,0),0) -> 0 | T170: =IFERROR(VLOOKUP(D170,#REF!,4,0),0) -> 0
A171: =VLOOKUP(INVENTARIO!$D171,LISTA!$A:$E,3,0) -> CYM-FQ | B171: =VLOOKUP(INVENTARIO!$D171,LISTA!$A:$E,4,0) -> Sangría | C171: =VLOOKUP(INVENTARIO!$D171,LISTA!$A:$E,5,0) -> Caroreña | D171: FR0137 | E171: SANGRIA CAROREÑA VERANO LAT250MLx12UN | F171: 12 | G171: =Q171 -> 0 | H171: =G171 -> 0 | K171: =R171 -> 0 | M171: =S171 -> 0 | P171: =H171-J171-I171-K171-L171-M171-INVENTARIO!$N171-O171 -> 0 | Q171: =IFERROR(VLOOKUP(D171,'TABL COMPR'!$A:$D,4,0),0) -> 0 | R171: =IFERROR(VLOOKUP(D171,#REF!,4,0),0) -> 0 | S171: =IFERROR(VLOOKUP(D171,#REF!,4,0),0) -> 0 | T171: =IFERROR(VLOOKUP(D171,#REF!,4,0),0) -> 0
...

Sheet TABL COMPR
A3: CodProducto | B3: DescrProducto | C3: UnidadCompra | D3: Suma de Cantidad
A4: (en blanco) | B4: (en blanco) | C4: (en blanco) | E4: =VLOOKUP(A4,INVENTARIO!$D:$E,1,0) -> #N/A | F4: =A4=E4 -> #N/A
A5: Total general | E5: =VLOOKUP(A5,INVENTARIO!$D:$E,1,0) -> #N/A | F5: =A5=E5 -> #N/A
E6: =VLOOKUP(A6,INVENTARIO!$D:$E,1,0) -> #N/A | F6: =A6=E6 -> #N/A
E7: =VLOOKUP(A7,INVENTARIO!$D:$E,1,0) -> #N/A | F7: =A7=E7 -> #N/A
E8: =VLOOKUP(A8,INVENTARIO!$D:$E,1,0) -> #N/A | F8: =A8=E8 -> #N/A
E9: =VLOOKUP(A9,INVENTARIO!$D:$E,1,0) -> #N/A | F9: =A9=E9 -> #N/A
E10: =VLOOKUP(A10,INVENTARIO!$D:$E,1,0) -> #N/A | F10: =A10=E10 -> #N/A
E11: =VLOOKUP(A11,INVENTARIO!$D:$E,1,0) -> #N/A | F11: =A11=E11 -> #N/A
E12: =VLOOKUP(A12,INVENTARIO!$D:$E,1,0) -> #N/A | F12: =A12=E12 -> #N/A
E13: =VLOOKUP(A13,INVENTARIO!$D:$E,1,0) -> #N/A | F13: =A13=E13 -> #N/A
E14: =VLOOKUP(A14,INVENTARIO!$D:$E,1,0) -> #N/A | F14: =A14=E14 -> #N/A
E15: =VLOOKUP(A15,INVENTARIO!$D:$E,1,0) -> #N/A | F15: =A15=E15 -> #N/A
E16: =VLOOKUP(A16,INVENTARIO!$D:$E,1,0) -> #N/A | F16: =A16=E16 -> #N/A
E17: =VLOOKUP(A17,INVENTARIO!$D:$E,1,0) -> #N/A | F17: =A17=E17 -> #N/A
... E232: =VLOOKUP(A232,INVENTARIO!$D:$E,1,0) -> #N/A | F232: =A232=E232 -> #N/A

Sheet COMPRA 03,07
A1: CódigoCompra | B1: FechaCompra | C1: CodProducto | D1: DescrProducto | E1: CodCategoría | F1: DescrCategoría | G1: CodFamilia | H1: DescrFamilia | I1: CodMarca | J1: DescrMarca | K1: CodTipoInv | L1: DescrTipoInv | M1: CodProdProve | N1: Cantidad | O1: UnidadCompra | P1: PrecioUnitario | Q1: Subtotal | R1: Total con IVA | S1: Descuento | T1: Descuento, % | U1: Peso Neto | V1: Kilos | W1: Peso Bruto | X1: Volumen | Y1: CodTrans | Z1: DescTrans | AA1: CodCausTrans | AB1: DescCausTrans | AC1: CodigoUsuario | AD1: CedulaUsuario | AE1: NombreUsuario | AF1: TelfUsuario | AG1: DireccionUsuario | AH1: GrupoUsuario | AI1: CodigoProveedor | AJ1: RucProveedor | AK1: RazonSocial | AL1: DirecProveedor | AM1: FechaCreacion (Proveedor) | AN1: Tipo de proveedor | AO1: Tipo de proveedor (Nombre) | AP1: Tipo de compra | AQ1: Tipo de compra (Nombre) | AR1: EstaCompra | AS1: Comentario Detalle | AT1: NúmeroCompra | AU1: Comentario Cabecera | AV1: Fecha Ingreso a Sistema

Sheet LISTA
A1: Material | B1: Descripción | C1: NEGOCIO | D1: Categoría | E1: Marca | F1: Empaque | G1: UD por CJ | H1: IVA | I1: Art 18 Lisaea | J1: PC_FQ Und S/IVA | K1: PC_FQ Und C/IVA | L1: PC_FQ Caja S/IVA | M1: PC_FQ Caja C/IVA | N1: PV_FQ Und S/IVA | O1: PV_FQ Und C/IVA | P1: PV_FQ Caja S/IVA | Q1: PV_FQ Caja C/IVA | R1: Precio RDV Und S/IVA | S1: Precio RDV Und C/IVA
A2: FN0601 | B2: POMAR BRUT 0,75LxC12 (N) | C2: CYM-FQ | D2: Espumantes | E2: Pomar | F2: 0,750 KG | G2: 1 | H2: 16% | I2: 0.27 | J2: 12.11 | K2: 14.32 | L2: 12.11 | M2: 14.32 | N2: 13.79 | O2: 16 | P2: 13.79 | Q2: 16 | R2: 16.94 | S2: 20
A3: FN0603 | B3: POMAR BRUT 0,75LxC6 (N) | C3: CYM-FQ | D3: Espumantes | E3: Pomar | F3: 0,000 KG | G3: 1 | H3: 16% | I3: 0.27 | J3: 12.11 | K3: 14.32 | L3: 12.11 | M3: 14.32 | N3: 13.79 | O3: 16 | P3: 13.79 | Q3: 16 | R3: 16.94 | S3: 20
A4: FN0606 | B4: POMAR BRUT 0,75LxC12 EE (N) | C4: CYM-FQ | D4: Espumantes | E4: Pomar | F4: 0,750 KG | G4: 1 | H4: 16% | I4: 0.27 | J4: 43.14 | K4: 50.31 | L4: 43.14 | M4: 50.31 | N4: 48.27 | O4: 55.99 | P4: 48.27 | Q4: 55.99 | R4: 60.04 | S4: 69.99
A5: FN0610 | B5: POMAR BRUT NATURE 0,75LxC12 (N) | C5: CYM-FQ | D5: Espumantes | E5: Pomar | F5: 0,750 KG | G5: 1 | H5: 16% | I5: 0.27 | J5: 13.97 | K5: 16.48 | L5: 13.97 | M5: 16.48 | N5: 15.86 | O5: 18.4 | P5: 15.86 | Q5: 18.4 | R5: 19.53 | S5: 23
A6: FN0612 | B6: POMAR DEMISEC 0,75LxC12 (N) | C6: CYM-FQ | D6: Espumantes | E6: Pomar | F6: 0,750 KG | G6: 1 | H6: 16% | I6: 0.27 | J6: 12.11 | K6: 14.32 | L6: 12.11 | M6: 14.32 | N6: 13.79 | O6: 16 | P6: 13.79 | Q6: 16 | R6: 16.94 | S6: 20
A7: FN0614 | B7: POMAR DEMISEC 0,75LxC6 (N) | C7: CYM-FQ | D7: Espumantes | E7: Pomar | F7: 0,000 KG | G7: 1 | H7: 16% | I7: 0.27 | J7: 12.11 | K7: 14.32 | L7: 12.11 | M7: 14.32 | N7: 13.79 | O7: 16 | P7: 13.79 | Q7: 16 | R7: 16.94 | S7: 20
A8: FN0615 | B8: POMAR BRUT ROSE 0,75LxC12 (N) | C8: CYM-FQ | D8: Espumantes | E8: Pomar | F8: 0,750 KG | G8: 1 | H8: 16% | I8: 0.27 | J8: 13.97 | K8: 16.48 | L8: 13.97 | M8: 16.48 | N8: 15.86 | O8: 18.4 | P8: 15.86 | Q8: 18.4 | R8: 19.53 | S8: 23
A9: FN0617 | B9: POMAR BRUT ROSE 0,75LxC6 (N) | C9: CYM-FQ | D9: Espumantes | E9: Pomar | F9: 0,750 KG | G9: 1 | H9: 16% | I9: 0.27 | J9: 13.97 | K9: 16.48 | L9: 13.97 | M9: 16.48 | N9: 15.86 | O9: 18.4 | P9: 15.86 | Q9: 18.4 | R9: 19.53 | S9: 23
A10: FN0625 | B10: POMAR BRUT E/E 0,75LxC6 (N) | C10: CYM-FQ | D10: Espumantes | E10: Pomar | F10: 0,000 KG | G10: 1 | H10: 16% | I10: 0.27 | J10: 43.14 | K10: 50.31 | L10: 43.14 | M10: 50.31 | N10: 48.27 | O10: 55.99 | P10: 48.27 | Q10: 55.99 | R10: 60.04 | S10: 69.99
A11: F04005 | B11: POLAR LIGHT RET 222MLx36UN | C11: CYM-FQ | D11: Light | E11: Polar Light | F11: 8,232 KG | G11: 36 | H11: 16% | I11: 2.24 | J11: 0.41 | K11: 0.54 | L11: 14.93 | M11: 19.56 | N11: 0.55 | O11: 0.64 | P11: 19.82 | Q11: 22.99 | R11: 22.53 | S11: 28.74
A12: F04014 | B12: POLAR LIGHT LAT 250MLx24UN | C12: CYM-FQ | D12: Light | E12: Polar Light | F12: 6,180 KG | G12: 24 | H12: 16% | I12: 2.16 | J12: 0.64 | K12: 0.83 | L12: 15.37 | M12: 19.99 | N12: 0.8 | O12: 0.92 | P12: 19.12 | Q12: 22.18 | R12: 21.73 | S12: 27.72
A13: F04017 | B13: POLAR LIGHT BAR 30Lx1PZ | C13: CYM-FQ | D13: Light | E13: Polar Light | F13: 0,000 KG | G13: 1 | H13: 16% | I13: 6.74 | J13: 58.44 | K13: 74.53 | L13: 58.44 | M13: 74.53 | N13: 74.35 | O13: 86.25 | P13: 74.35 | Q13: 86.25 | R13: 67.6 | S13: 86.25
... A57: FR0149 | B57: SANGRIA LA QUE MANDA ROSADA 1,75LX6UN | C57: CYM-FQ | D57: Sangría | E57: La Que Manda | F57: 10,659 KG | G57: 6 | H57: 16% | I57: 4.99 | J57: 2.82 | K57: 4.11 | L57: 16.94 | M57: 24.64 | N57: 4.11 | O57: 4.77 | P57: 24.68 | Q57: 28.63 | R57: 24.47 | S57: 34.5
A58: FR0159 | B58: SANGRIA CAROREÑA VERANO MOJITO LAT355x24 | C58: CYM-FQ | D58: Sangría | E58: Caroreña | G58: 24
A59: FR0160 | B59: SANGRIA LA QUE MANDA TINTA LAT250MLx24UN | C59: CYM-FQ | D59: Sangría | E59: La Que Manda | G59: 24
A60: F07103 | B60: MALTIN POLAR COCO LAT 250MLx24UN | C60: CYM-FQ | D60: Malta | E60: Maltin Polar | G60: 24
A61: F06066 | B61: KIT POLAR FEST NR 3,728L 2023 | C61: CYM-FQ | D61: Temporada | E61: Temporada | F61: 3,728 KG | G61: 12 | H61: 16% | I61: 1.17 | J61: 0.69 | K61: 0.9 | L61: 8.31 | M61: 10.81 | N61: 0.86 | O61: 1 | P61: 10.34 | Q61: 11.99 | R61: 11.75 | S61: 15
A62: F01001 | B62: POLAR PILSEN RET 222MLx36UN | C62: CYM-FQ | D62: Tradicional | E62: Polar Pilsen | F62: 8,032 KG | G62: 36 | H62: 16% | I62: 2.24 | J62: 0.41 | K62: 0.54 | L62: 14.93 | M62: 19.56 | N62: 0.55 | O62: 0.64 | P62: 19.82 | Q62: 22.99 | R62: 22.53 | S62: 28.74
A63: F01002 | B63: POLAR PILSEN RET 330MLx24UN | C63: CYM-FQ | D63: Tradicional | E63: Polar Pilsen | F63: 7,960 KG | G63: 24 | H63: 16% | I63: 2 | J63: 0.56 | K63: 0.73 | L63: 13.34 | M63: 17.47 | N63: 0.74 | O63: 0.86 | P63: 17.7 | Q63: 20.53 | R63: 20.12 | S63: 25.67
A64: F01003 | B64: POLAR PILSEN LAT 250MLx24UN | C64: CYM-FQ | D64: Tradicional | E64: Polar Pilsen | F64: 6,030 KG | G64: 24 | H64: 16% | I64: 2.16 | J64: 0.64 | K64: 0.83 | L64: 15.37 | M64: 19.99 | N64: 0.8 | O64: 0.92 | P64: 19.12 | Q64: 22.18 | R64: 21.73 | S64: 27.72
A65: F01004 | B65: POLAR PILSEN BAR 50Lx1PZ | C65: CYM-FQ | D65: Tradicional | E65: Polar Pilsen | F65: 0,000 KG | G65: 1 | H65: 16% | I65: 12.52 | J65: 108.54 | K65: 138.43 | L65: 108.54 | M65: 138.43 | N65: 138.08 | O65: 160.17 | P65: 138.08 | Q65: 160.17 | R65: 125.55 | S65: 160.17
A66: F01005 | B66: POLAR PILSEN BAR 30Lx1PZ | C66: CYM-FQ | D66: Tradicional | E66: Polar Pilsen | F66: 30,150 KG | G66: 1 | H66: 16% | I66: 6.74 | J66: 58.44 | K66: 74.53 | L66: 58.44 | M66: 74.53 | N66: 74.35 | O66: 86.25 | P66: 74.35 | Q66: 86.25 | R66: 67.6 | S66: 86.25
A67: F01063 | B67: POLAR PILSEN NR 355MLx12UN | C67: CYM-FQ | D67: Tradicional | E67: Polar Pilsen | F67: 4,281 KG | G67: 12 | H67: 16% | I67: 1.48 | J67: 0.88 | K67: 1.14 | L67: 10.53 | M67: 13.69 | N67: 1.09 | O67: 1.27 | P67: 13.1 | Q67: 15.2 | R67: 14.89 | S67: 19
A68: F01077 | B68: POLAR PILSEN LAT SLEEK 355MLx12UN | C68: CYM-FQ | D68: Tradicional | E68: Polar Pilsen | F68: 4,281 KG | G68: 12 | H68: 16% | I68: 1.3 | J68: 0.77 | K68: 1 | L68: 9.24 | M68: 12.02 | N68: 0.96 | O68: 1.11 | P68: 11.5 | Q68: 13.34 | R68: 13.07 | S68: 16.68
A69: F01081 | B69: POLAR FEST LAT SLEEK 355MLx12UN | C69: CYM-FQ | D69: Tradicional | E69: Polar Pilsen | F69: 4,281 KG | G69: 12 | H69: 16% | I69: 1.3 | J69: 0.77 | K69: 1 | L69: 9.24 | M69: 12.02 | N69: 0.96 | O69: 1.11 | P69: 11.5 | Q69: 13.34 | R69: 13.07 | S69: 16.68
A70: F01083 | B70: POLAR PILSEN LAT SLEEK 355MLx24UN | C70: CYM-FQ | D70: Tradicional | E70: Polar Pilsen | F70: 8,563 KG | G70: 24 | H70: 16% | I70: 2.61 | J70: 0.77 | K70: 1 | L70: 18.51 | M70: 24.08 | N70: 0.96 | O70: 1.11 | P70: 23.02 | Q70: 26.7 | R70: 26.16 | S70: 33.37
A71: FN0301 | B71: POMAR FRIZZANTE 0,75LxC12 (N) | C71: CYM-FQ | D71: Vino Nacional | E71: Pomar | F71: 0,750 KG | G71: 1 | H71: 16% | I71: 0.27 | J71: 5.92 | K71: 7.14 | L71: 5.92 | M71: 7.14 | N71: 6.9 | O71: 8 | P71: 6.9 | Q71: 8 | R71: 8.33 | S71: 10
A72: FN0304 | B72: POMAR FRIZZANTE ROSADO 0,75LxC12 (N) | C72: CYM-FQ | D72: Vino Nacional | E72: Pomar | F72: 0,750 KG | G72: 1 | H72: 16% | I72: 0.27 | J72: 5.92 | K72: 7.14 | L72: 5.92 | M72: 7.14 | N72: 6.9 | O72: 8 | P72: 6.9 | Q72: 8 | R72: 8.33 | S72: 10
... A77: FN0117 | B77: POMAR TINTO 0,75LxC12 (N) | C77: CYM-FQ | D77: Vino Nacional | E77: Terracota | F77: 0,750 KG | G77: 1 | H77: 16% | I77: 0.27 | J77: 4.67 | K77: 5.69 | L77: 4.67 | M77: 5.69 | N77: 5.52 | O77: 6.4 | P77: 5.52 | Q77: 6.4 | R77: 6.6 | S77: 8
A78: 1017662 | B78: MINALBA SPARKLING NARANJA PET500MLx12U | C78: PCV-FQ | D78: AGUA | E78: MINALBA | G78: 12 | H78: 16% | I78: 0.9 | J78: 1.05 | K78: 10.85 | L78: 12.59 | M78: 0.96 | N78: 1.12 | O78: 11.55 | P78: 13.4 | Q78: 1.15 | R78: 1.34
A79: 1017272 | B79: MINALBA SPARKLING LIMON PET 1Lx6UN | C79: PCV-FQ | D79: AGUA | E79: MINALBA | G79: 6 | H79: 16% | I79: 1.58 | J79: 1.83 | K79: 9.49 | L79: 11.01 | M79: 1.68 | N79: 1.95 | O79: 10.1 | P79: 11.72 | Q79: 2.02 | R79: 2.34
A80: 1017271 | B80: MINALBA SPARKLING PET 1Lx6UN | C80: PCV-FQ | D80: AGUA | E80: MINALBA | G80: 6 | H80: 16% | I80: 1.58 | J80: 1.83 | K80: 9.49 | L80: 11.01 | M80: 1.68 | N80: 1.95 | O80: 10.1 | P80: 11.72 | Q80: 2.02 | R80: 2.34
A81: 1017031 | B81: MINALBA SPARKLING TORONJA PET500MLx12U | C81: PCV-FQ | D81: AGUA | E81: MINALBA | G81: 12 | H81: 16% | I81: 0.9 | J81: 1.05 | K81: 10.85 | L81: 12.59 | M81: 0.96 | N81: 1.12 | O81: 11.55 | P81: 13.4 | Q81: 1.15 | R81: 1.34
A82: 1016692 | B82: MINALBA SPARKLING LIMON PET500MLx12UN | C82: PCV-FQ | D82: AGUA | E82: MINALBA | G82: 12 | H82: 16% | I82: 0.9 | J82: 1.05 | K82: 10.85 | L82: 12.59 | M82: 0.96 | N82: 1.12 | O82: 11.55 | P82: 13.4 | Q82: 1.15 | R82: 1.34
A83: 1016691 | B83: MINALBA SPARKLING PET 500MLx12UN | C83: PCV-FQ | D83: AGUA | E83: MINALBA | G83: 12 | H83: 16% | I83: 0.9 | J83: 1.05 | K83: 10.85 | L83: 12.59 | M83: 0.96 | N83: 1.12 | O83: 11.55 | P83: 13.4 | Q83: 1.15 | R83: 1.34
A84: 1013371 | B84: MINALBA AGUA PET 355MLx24UN | C84: PCV-FQ | D84: AGUA | E84: MINALBA | G84: 24 | H84: 16% | I84: 0.54 | J84: 0.62 | K84: 12.86 | L84: 14.92 | M84: 0.57 | N84: 0.66 | O84: 13.68 | P84: 15.87 | Q84: 0.68 | R84: 0.79
A85: 123517 | B85: MINALBA AGUA PET TR 600MLx24UN | C85: PCV-FQ | D85: AGUA | E85: MINALBA | G85: 24 | H85: 16% | I85: 0.68 | J85: 0.79 | K85: 16.32 | L85: 18.93 | M85: 0.72 | N85: 0.84 | O85: 17.36 | P85: 20.14 | Q85: 0.86 | R85: 1
A86: 95723 | B86: MINALBA AGUA PET S/G 5Lx2UN | C86: PCV-FQ | D86: AGUA | E86: MINALBA | G86: 2 | H86: 16% | I86: 3.72 | J86: 4.32 | K86: 7.44 | L86: 8.63 | M86: 3.96 | N86: 4.59 | O86: 7.92 | P86: 9.19 | Q86: 4.71 | R86: 5.46
A87: 95722 | B87: MINALBA AGUA PET S/G 1,5Lx12UN | C87: PCV-FQ | D87: AGUA | E87: MINALBA | G87: 12 | H87: 16% | I87: 1.26 | J87: 1.46 | K87: 15.15 | L87: 17.57 | M87: 1.34 | N87: 1.56 | O87: 16.12 | P87: 18.7 | Q87: 1.59 | R87: 1.84
...
